<mujoco>
    <!-- <default>
        <joint damping=".03" actuatorforcerange="-0.5 0.5"/>
    </default> -->
    <compiler angle="degree" coordinate="local" inertiafromgeom="true" />
    <option integrator="RK4" timestep="0.0001" />

    <asset>
        <texture type="skybox" builtin="gradient" rgb1="0.3 0.5 0.7" rgb2="0 0 0" width="512" height="3072"/>
        <texture type="2d" name="groundplane" builtin="checker" mark="edge" rgb1="0.2 0.3 0.4" rgb2="0.1 0.2 0.3" markrgb="0.8 0.8 0.8" width="300" height="300"/>
        <material name="groundplane" texture="groundplane" texuniform="true" texrepeat="5 5" reflectance="0.2"/>
    </asset>

    <worldbody>
        <!-- <geom type="plane" size="50 50 .01" rgba="0.6 1 0 1" /> -->
        <geom type="plane" size="30 30 .01" material="groundplane"/>
      <light pos="0 0 1.5" dir="0 0 -1" directional="true"/>

        <body pos="0 0 2.8e-3">
            <freejoint />
            <body name="torso" >
            <geom name="mein_body1" type="box" size="0.05 0.03 0.0016" friction="0.0 0.0 0.0" rgba="0.05 0.4 0.15 1" pos="0 0 0.001" mass="4.65e-3"/>
            <geom name="mein_body_chip1" type="box" size="0.00707 0.00707 0.0016" friction="0.0 0.0 0.0" rgba="0.05 0.4 0.15 1" pos="0.04 0.03 0.001" euler="0 0 45" mass="4.65e-3"/>
            <geom name="mein_body_chip2" type="box" size="0.00707 0.00707 0.0016" friction="0.0 0.0 0.0" rgba="0.05 0.4 0.15 1" pos="0.04 -0.03 0.001" euler="0 0 45" mass="4.65e-3"/>
            <geom name="mein_body_chip3" type="box" size="0.00707 0.00707 0.0016" friction="0.0 0.0 0.0" rgba="0.05 0.4 0.15 1" pos="-0.04 0.03 0.001" euler="0 0 45" mass="4.65e-3"/>
            <geom name="mein_body_chip4" type="box" size="0.00707 0.00707 0.0016" friction="0.0 0.0 0.0" rgba="0.05 0.4 0.15 1" pos="-0.04 -0.03 0.001" euler="0 0 45" mass="4.65e-3"/>
            <geom name="mein_body4" type="box" size="0.013 0.04 0.0016" friction="0.0 0.0 0.0" rgba="0.05 0.4 0.15 1" pos="-0.027 0 0.001" mass="4.65e-3"/>
            <geom name="mein_body5" type="box" size="0.013 0.04 0.0016" friction="0.0 0.0 0.0" rgba="0.05 0.4 0.15 1" pos="0.027 0 0.001" mass="4.65e-3"/>
                <site name = "hit_box" type = "box" size = "0.02 0.043 0.0016" pos="0.032 0 0.003" rgba=".5 .2 0 .1"/> 接触判定領域（この中に入ってるgeomが接触すると，センサ値としてその値を取得できる）
                <site name = "hit_box2" type = "box" size = "0.02 0.043 0.0016" pos="-0.032 0 0.003" rgba=".5 .2 0 .1"/>
                <camera name="camera_name" mode="track" pos="-0.2 0 1" euler="0 -20 -90" fovy="60"/> トラッキングカメラを装着
            </body>
            
            <site name="sensor_left_front" type="box" size="0.003 0.003 0.003" pos="0.031 0.036 0.01" zaxis="1 0 0.08" rgba=".5 1 .5 1"/>
              <!-- zaxisの３つめ　0.1でちょい上向き -->
            <site name="sensor_left_side" type="box" size="0.003 0.003 0.003" pos="0.043 0.016 0.01" zaxis="0.25 1 0" rgba=".5 1 .5 1"/>
            <site name="sensor_right_front" type="box" size="0.003 0.003 0.003" pos="0.031 -0.036 0.01" zaxis="1 0 0.08" rgba=".5 1 .5 1"/>
            <site name="sensor_right_side" type="box" size="0.003 0.003 0.003" pos="0.043 -0.016 0.01" zaxis="0.25 -1 0" rgba=".5 1 .5 1"/>
            <!-- <site name = "hit_box" type = "box" size = "0.02 0.05 0.0005" pos="0.04 0 0.002" rgba=".5 .2 0 .3"/>
            <site name = "hit_box2" type = "box" size = "0.02 0.05 0.0005" pos="-0.04 0 0.002" rgba=".5 .2 0 .3"/> -->

            <!-- <body name="left wheel" pos="-0.0 0.036 0.0117" zaxis="0 1 0"> -->
             <body name="left wheel" pos="-0.0 0.036 0.0125" zaxis="0 1 0">
                <joint name="left wheel joint" type="hinge" axis="0 0 1" limited="false" damping='5.4e-5' />
                
                <geom type="cylinder" size="0.0135 0.0035" rgba=".3 .3 0.3 1" mass="1.0e-2"/>
                <site type="box" size = "0.0012 0.008 0.004" rgba=".5 1 .5 1"/>
            </body>
            
            <body name="right wheel" pos="-0.0 -0.036 0.0125" zaxis="0 1 0">
                <joint name="right wheel joint" type="hinge" axis="0 0 1" limited="false" damping='5.4e-5' />
                <geom type="cylinder" size="0.0135 0.0035" rgba=".3 .3 0.3 1" mass="1.0e-2"/>
                <site type="box" size = "0.0012 0.008 0.004" rgba=".5 1 .5 1"/>
            </body>

            <body name="motorbox1" pos="0 -0.018 0.0135" >
                <geom type="box" size="0.01 0.0135 0.01" rgba="0.1 0.1 0.1 1" mass="5.52e-2"/>
            </body>

            <body name="motorbox2" pos="0 0.018 0.0135">
                <geom type="box" size="0.01 0.0135 0.01" rgba="0.1 0.1 0.1 1" mass="5.52e-2"/>
            </body>

        </body>
    <!-- <site type="box" rgba="1 0 0 0.1" fromto="0 0 0 2 0 0" size="0.01"/>
    <site type="box" rgba="0 1 0 0.1" fromto="0 0 0 0 2 0" size="0.01"/>
    <site type="box" rgba="0 0 1 0.1" fromto="0 0 0 0 0 2" size="0.01"/> --> 座標軸表示



        <!-- <body name="wall" pos="7 0.0 0">
                <geom type="box" size="0.1 2 0.3" rgba=".5 .5 1 1" />
            </body> -->

        <body name="back_wall" pos="-0.09 0 0.025">
                <geom type="box" size="0.005 0.18 0.025" rgba="0.4 0 0 1" />
            </body>
<!-- 
        <body name="side_wall1" pos="0 3 2">
        <freejoint />
                <geom type="box" size="2 0.1 0.3" rgba=".5 .5 1 1" />
            </body> -->
<!-- 
        <body name="side_wall2" pos="0 -3 2">
        <freejoint />
                <geom type="box" size="2 0.1 0.3" rgba=".5 .5 1 1" />
            </body> -->
<!-- 
        <body name="maze_init_wall_outline" pos="0 0.09 0.025">
                <geom type="box" size="0.09 0.005 0.025" rgba=".5 .5 .3 0.5" pos="0 -0.18 0.0"/>
          
                <geom type="box" size="0.09 0.005 0.025" rgba="1 0 0 1" pos="0.18 0 0"/>
                <geom type="box" size="0.09 0.005 0.025" rgba="1 0 0 1" pos="0.36 0 0"/>
                <geom type="box" size="0.09 0.005 0.025" rgba="1 0 0 1" pos="0.54 0 0"/>
                <geom type="box" size="0.09 0.005 0.025" rgba="1 0 0 1" pos="0.72 0 0"/>
                <geom type="box" size="0.09 0.005 0.025" rgba="1 0 0 1" pos="0.90 0 0"/>
                <geom type="box" size="0.09 0.005 0.025" rgba="1 0 0 1" pos="1.08 0 0"/>
                <geom type="box" size="0.09 0.005 0.025" rgba="1 0 0 1" pos="1.26 0 0"/>

                <geom type="box" size="0.005 0.09 0.025" rgba="1 0 0 1" pos="0.81 -0.09 0"/>
                <geom type="box" size="0.005 0.09 0.025" rgba="1 0 0 1" pos="0.81 -0.18 0"/>
                <geom type="box" size="0.005 0.09 0.025" rgba="1 0 0 1" pos="0.81 -0.36 0"/>
                <geom type="box" size="0.005 0.09 0.025" rgba="1 0 0 1" pos="0.81 -0.54 0"/>
                <geom type="box" size="0.005 0.18 0.025" rgba="1 0 0 1" pos="0.81 -0.72 0"/>

                <geom type="box" size="0.09 0.005 0.025" rgba=".5 .5 .3 0.5" />
                <geom type="box" size="0.09 0.005 0.025" rgba="1 0 0 0.4" pos="0.0 -0.90 0"/>
                <geom type="box" size="0.09 0.005 0.025" rgba="1 0 0 0.4" pos="0.18 -0.90 0"/>
                <geom type="box" size="0.09 0.005 0.025" rgba="1 0 0 0.4" pos="0.36 -0.90 0"/>
                <geom type="box" size="0.09 0.005 0.025" rgba="1 0 0 0.4" pos="0.54 -0.90 0"/>
                <geom type="box" size="0.09 0.005 0.025" rgba="1 0 0 0.4" pos="0.72 -0.90 0"/>

                <geom type="box" size="0.005 0.09 0.025" rgba=".5 .5 .3 0.5" pos="-0.09 -0.09 0"/>
                <geom type="box" size="0.005 0.09 0.025" rgba="1 0 0 1" pos="-0.09 -0.18 0"/>
                <geom type="box" size="0.005 0.09 0.025" rgba="1 0 0 1" pos="-0.09 -0.36 0"/>
                <geom type="box" size="0.005 0.09 0.025" rgba="1 0 0 1" pos="-0.09 -0.54 0"/>
                <geom type="box" size="0.005 0.18 0.025" rgba="1 0 0 1" pos="-0.09 -0.72 0"/>
            </body> -->



<!-- かべかべかべｎ --><!-- かべかべかべｎ --><!-- かべかべかべｎ --><!-- かべかべかべｎ --><!-- かべかべかべｎ -->

        <body name="maze_wall2" pos="1.9 -0.1 0.025">
                <geom type="box" size="8 0.005 0.025" rgba=".5 .5 1 1" />
            </body>
            <body name="long_wall2" pos="1.9 0.1 0.025">
                <geom type="box" size="8 0.005 0.025" rgba=".5 .5 1 1" />
            </body>
<!-- かべかべかべｎ --><!-- かべかべかべｎ --><!-- かべかべかべｎ --><!-- かべかべかべｎ --><!-- かべかべかべｎ -->
            

            <!-- <body name="goal1" pos="2 0 0.045">
                <geom name="goal" type="sphere" size="0.03" rgba="1 1 0 1" />
                <site name="goal" type="sphere" size="0.15" rgba="0 1 0.2 0.2" />
            </body>
      -->




    </worldbody>
    <actuator>
        <!-- <motor name="right" joint="right wheel joint" gear="1.8e-3" ctrllimited="true" ctrlrange="-3 3"/> ctrlrangeで入力の値の範囲を決められる
        <motor name="left" joint="left wheel joint" gear="1.8e-3" ctrllimited="true" ctrlrange="-3 3"/> -->
        <motor name="right" joint="right wheel joint" gear="0.3e-2" ctrllimited="true" ctrlrange="-3 3"/> ctrlrangeで入力の値の範囲を決められる
        <motor name="left" joint="left wheel joint" gear="0.3e-2" ctrllimited="true" ctrlrange="-3 3"/>
    </actuator>

    <sensor>
        <rangefinder name="LF" site="sensor_left_front" cutoff="0.15"/>
        <rangefinder name="LS" site="sensor_left_side" cutoff="0.15"/>
        <rangefinder name="RF" site="sensor_right_front" cutoff="0.15"/>
        <rangefinder name="RS" site="sensor_right_side" cutoff="0.15"/>
        <touch name = "HB" site = "hit_box"/>
        <touch name = "HB2" site = "hit_box2"/>
    </sensor>
</mujoco>